ERROR:tornado.application:Uncaught exception POST /julygroup9_web/api/sign/in (127.0.0.1)
HTTPServerRequest(protocol='http', host='group9_web_server_stream', method='POST', uri='/julygroup9_web/api/sign/in', version='HTTP/1.1', remote_ip='127.0.0.1')
Traceback (most recent call last):
  File "/home/prithviraj/icfai/july21group9/server/sign_in.py", line 83, in post
    self.write(response)
  File "/usr/local/lib/python3.9/dist-packages/tornado/web.py", line 843, in write
    chunk = escape.json_encode(chunk)
  File "/usr/local/lib/python3.9/dist-packages/tornado/escape.py", line 75, in json_encode
    return json.dumps(value).replace("</", "<\\/")
  File "/usr/lib/python3.9/json/__init__.py", line 231, in dumps
    return _default_encoder.encode(obj)
  File "/usr/lib/python3.9/json/encoder.py", line 199, in encode
    chunks = self.iterencode(o, _one_shot=True)
  File "/usr/lib/python3.9/json/encoder.py", line 257, in iterencode
    return _iterencode(o, 0)
  File "/usr/lib/python3.9/json/encoder.py", line 179, in default
    raise TypeError(f'Object of type {o.__class__.__name__} '
TypeError: Object of type bytes is not JSON serializable

During handling of the above exception, another exception occurred:

Traceback (most recent call last):
  File "/home/prithviraj/icfai/july21group9/server/sign_in.py", line 96, in post
    self.write(response)
  File "/usr/local/lib/python3.9/dist-packages/tornado/web.py", line 843, in write
    chunk = escape.json_encode(chunk)
  File "/usr/local/lib/python3.9/dist-packages/tornado/escape.py", line 75, in json_encode
    return json.dumps(value).replace("</", "<\\/")
  File "/usr/lib/python3.9/json/__init__.py", line 231, in dumps
    return _default_encoder.encode(obj)
  File "/usr/lib/python3.9/json/encoder.py", line 199, in encode
    chunks = self.iterencode(o, _one_shot=True)
  File "/usr/lib/python3.9/json/encoder.py", line 257, in iterencode
    return _iterencode(o, 0)
  File "/usr/lib/python3.9/json/encoder.py", line 179, in default
    raise TypeError(f'Object of type {o.__class__.__name__} '
TypeError: Object of type bytes is not JSON serializable

During handling of the above exception, another exception occurred:

Traceback (most recent call last):
  File "/home/prithviraj/icfai/july21group9/server/sign_in.py", line 100, in post
    raise Exception
Exception

During handling of the above exception, another exception occurred:

Traceback (most recent call last):
  File "/usr/local/lib/python3.9/dist-packages/tornado/web.py", line 1704, in _execute
    result = await result
  File "/home/prithviraj/icfai/july21group9/server/sign_in.py", line 108, in post
    self.write(response)
  File "/usr/local/lib/python3.9/dist-packages/tornado/web.py", line 843, in write
    chunk = escape.json_encode(chunk)
  File "/usr/local/lib/python3.9/dist-packages/tornado/escape.py", line 75, in json_encode
    return json.dumps(value).replace("</", "<\\/")
  File "/usr/lib/python3.9/json/__init__.py", line 231, in dumps
    return _default_encoder.encode(obj)
  File "/usr/lib/python3.9/json/encoder.py", line 199, in encode
    chunks = self.iterencode(o, _one_shot=True)
  File "/usr/lib/python3.9/json/encoder.py", line 257, in iterencode
    return _iterencode(o, 0)
  File "/usr/lib/python3.9/json/encoder.py", line 179, in default
    raise TypeError(f'Object of type {o.__class__.__name__} '
TypeError: Object of type bytes is not JSON serializable
ERROR:tornado.access:500 POST /julygroup9_web/api/sign/in (127.0.0.1) 20.60ms
Traceback (most recent call last):
  File "/home/soumik/1_xlayer_training/july21group9/server/group9_server.py", line 1, in <module>
    from common_library import *
  File "/home/soumik/1_xlayer_training/july21group9/server/common_library.py", line 1, in <module>
    import tornado.ioloop
ModuleNotFoundError: No module named 'tornado'
mkdir: cannot create directory ‘./log’: File exists
mkdir: cannot create directory ‘./log’: File exists
Traceback (most recent call last):
  File "group9_server.py", line 27, in <module>
    app().listen(8009)
  File "/home/soumik/.local/lib/python3.8/site-packages/tornado/web.py", line 2109, in listen
    server.listen(port, address)
  File "/home/soumik/.local/lib/python3.8/site-packages/tornado/tcpserver.py", line 151, in listen
    sockets = bind_sockets(port, address=address)
  File "/home/soumik/.local/lib/python3.8/site-packages/tornado/netutil.py", line 161, in bind_sockets
    sock.bind(sockaddr)
OSError: [Errno 98] Address already in use
Traceback (most recent call last):
  File "group9_server.py", line 27, in <module>
    app().listen(8009)
  File "/home/soumik/.local/lib/python3.8/site-packages/tornado/web.py", line 2109, in listen
    server.listen(port, address)
  File "/home/soumik/.local/lib/python3.8/site-packages/tornado/tcpserver.py", line 151, in listen
    sockets = bind_sockets(port, address=address)
  File "/home/soumik/.local/lib/python3.8/site-packages/tornado/netutil.py", line 161, in bind_sockets
    sock.bind(sockaddr)
OSError: [Errno 98] Address already in use
Traceback (most recent call last):
  File "group9_server.py", line 27, in <module>
    app().listen(8009)
  File "/home/soumik/.local/lib/python3.8/site-packages/tornado/web.py", line 2109, in listen
    server.listen(port, address)
  File "/home/soumik/.local/lib/python3.8/site-packages/tornado/tcpserver.py", line 151, in listen
    sockets = bind_sockets(port, address=address)
  File "/home/soumik/.local/lib/python3.8/site-packages/tornado/netutil.py", line 161, in bind_sockets
    sock.bind(sockaddr)
OSError: [Errno 98] Address already in use
Traceback (most recent call last):
  File "/home/soumik/1_xlayer_training/july21group9/server/group9_server.py", line 1, in <module>
    from common_library import *
  File "/home/soumik/1_xlayer_training/july21group9/server/common_library.py", line 1, in <module>
    import tornado.ioloop
ModuleNotFoundError: No module named 'tornado'
